Workbook

Sheet Start Here
A1: Painting Estimator — Hybrid Inputs (Manual or App)
A3: How to use:
A4: 1) Manual entry: fill green cells in INPUT_* tabs (Rooms, Segments, Openings, Doors, PreJob).
A5: 2) App entry: write the same tables via API. Formulas live only in Engine/Summary/Estimate Builder.
A6: 3) Main job rounding: Summary rounds MAIN labor to 0.5 day; PreJob totals stay separate and are added after.
A8: Key design rules:
A9: - Inches-first inputs
A10: - Constants are single source of truth (add rows, avoid formula edits)
A11: - Scopes don't reference each other; they all reference INPUT_* tables

Sheet Job Control
A1: JOB CONTROL (optional for app integration)
A3: Active JobID
A4: Tip | B4: Engines/Summary/Estimate Builder read the JobID from this sheet. App can set it after syncing inputs.

Sheet Constants
A1: CONSTANTS — Single Source of Truth (add rows; avoid editing formulas)
A3: Guidance:
A4: • Add new rows within a section to expand (e.g., new OpeningType, DoorType, TrimItem).
A5: • Engines use wide ranges so adding rows usually requires no formula changes.
A6: • Keep keys unique within each table (e.g., OpeningType names).
A8: JOB DEFAULTS | E8: PREP FACTORS | H8: HEIGHT FACTORS (ft)
A9: Key | B9: Value | C9: Notes | E9: PrepLevel | F9: Factor | H9: MinFt | I9: Multiplier | J9: Notes
A10: DayHours | B10: 8 | C10: Workday length for rounding | E10: Light | F10: 1 | H10: 0 | I10: 1 | J10: 0–9ft
A11: RoundIncrementHours | B11: 4 | C11: Half-day rounding increment (hrs) | E11: Medium | F11: 1.35 | H11: 9 | I11: 1.15 | J11: 9–12ft
A12: LaborRate | B12: 65 | C12: Default labor rate ($/hr) | E12: Heavy | F12: 1.8 | H12: 12 | I12: 1.3 | J12: 12–16ft
A13: Markup | B13: 1.35 | C13: Default markup multiplier | H13: 16 | I13: 1.5 | J13: 16ft+
A14: WallCoverageSqftPerGalPerCoat | B14: 350 | C14: Coverage assumption
A15: CeilingCoverageSqftPerGalPerCoat | B15: 350 | C15: Coverage assumption
A16: TrimCoverageSqftPerGalPerCoat | B16: 350 | C16: Optional
A17: SchemaVersion | B17: v5 | C17: App checks this before writing inputs
A19: WALL LABOR MODEL (mins) | F19: CEILING LABOR MODEL (mins)
A20: Key | B20: Value | C20: Notes | F20: Key | G20: Value | H20: Notes
A21: PrepMinsPerSqft | B21: 0.12 | C21: Base prep mins/sqft | F21: PrepMinsPerSqft | G21: 0.1 | H21: Base prep mins/sqft
A22: PaintMinsPerSqftPerCoat | B22: 0.08 | C22: Paint mins/sqft per coat | F22: PaintMinsPerSqftPerCoat | G22: 0.09 | H22: Paint mins/sqft per coat
A23: PrimerFullMinsPerSqft | B23: 0.06 | C23: Primer mins/sqft for full prime | F23: PrimerFullMinsPerSqft | G23: 0.07 | H23: Primer mins/sqft for full prime
A24: PrimerSpotFactor | B24: 0.35 | C24: Multiply full-prime mins for spot prime | F24: PrimerSpotFactor | G24: 0.35 | H24: Multiply full-prime mins for spot prime
A29: OPENING TYPES (defaults) | H29: DOOR TYPES (per side mins)
A30: OpeningType | B30: Category | C30: DefaultWidth_in | D30: DefaultHeight_in | E30: CasingLF_default | F30: CutInMins_each | H30: DoorType | I30: PrepMins_perSide | J30: PaintMinsPerCoat_perSide | K30: PrimerMins_perSide
A31: Single Door | B31: Door | C31: 36 | D31: 80 | E31: 17 | F31: 12 | H31: Hollow Core | I31: 6 | J31: 8 | K31: 6
A32: Double Door | B32: Door | C32: 60 | D32: 80 | E32: 24 | F32: 18 | H32: 6 Panel | I32: 10 | J32: 14 | K32: 10
A33: Single Window | B33: Window | C33: 36 | D33: 48 | E33: 14 | F33: 10 | H33: Solid Core | I33: 12 | J33: 16 | K33: 12
A34: Double Window | B34: Window | C34: 72 | D34: 48 | E34: 22 | F34: 16 | H34: French | I34: 20 | J34: 24 | K34: 20
A35: Slider | B35: Door | C35: 72 | D35: 80 | E35: 0 | F35: 20
A39: TRIM ITEMS (mins)
A40: TrimItem | B40: Unit | C40: PrepMins_perUnit | D40: PaintMinsPerCoat_perUnit | E40: PrimerMins_perUnit | F40: Notes
A41: Baseboard | B41: LF | C41: 0.35 | D41: 0.25 | E41: 0.2
A42: Crown | B42: LF | C42: 0.45 | D42: 0.3 | E42: 0.25
A43: Window Casing | B43: LF | C43: 0.6 | D43: 0.35 | E43: 0.3
A44: Door Casing | B44: LF | C44: 0.7 | D44: 0.4 | E44: 0.35
A45: Doors (leaf) | B45: EA | C45: 0 | D45: 0 | E45: 0 | F45: (leaf mins come from Door Types)
A51: PAINT PRODUCTS (prices + coverage)
A52: Product | B52: Type | C52: Price_per_gal | D52: Coverage_sqft_per_gal_per_coat | E52: Sheen/Notes | F52: Active?
A53: SW ProMar 400 | B53: Wall | C53: 40 | D53: 350 | E53: eggshell/satin varies | F53: Y
A54: SW Duration | B54: Wall | C54: 70 | D54: 350 | F54: Y
A55: SW Emerald | B55: Wall | C55: 85 | D55: 350 | F55: Y
...

Sheet INPUT_JobSettings
A1: INPUT_JOBSETTINGS (per job paint selections + overrides)
A3: App-first: JobID is hidden; app writes it. Manual: unhide column A to edit.
A5: JobID | B5: WallsPaint_ID | C5: CeilingPaint_ID | D5: TrimPaint_ID | E5: Primer_ID | F5: Override_LaborRate | G5: Override_Markup | H5: RoundingIncrementHours | I5: DayHours | J5: Notes | K5: WallsPaint_Name (calc) | L5: CeilingPaint_Name (calc) | M5: TrimPaint_Name (calc) | N5: Primer_Name (calc) | O5: WallsPaint_gal_override | P5: CeilingPaint_gal_override | Q5: Primer_gal_override | R5: ExtraSupplies_Walls$ | S5: ExtraSupplies_Ceilings$ | T5: ExtraSupplies_Trim$
K6: =IF(B6="","", XLOOKUP(B6, Constants!$A$123:$A$2000, Constants!$B$123:$B$2000, "")) | L6: =IF(C6="","", XLOOKUP(C6, Constants!$A$123:$A$2000, Constants!$B$123:$B$2000, "")) | M6: =IF(D6="","", XLOOKUP(D6, Constants!$A$123:$A$2000, Constants!$B$123:$B$2000, "")) | N6: =IF(E6="","", XLOOKUP(E6, Constants!$A$123:$A$2000, Constants!$B$123:$B$2000, ""))
K7: =IF(B7="","", XLOOKUP(B7, Constants!$A$123:$A$2000, Constants!$B$123:$B$2000, "")) | L7: =IF(C7="","", XLOOKUP(C7, Constants!$A$123:$A$2000, Constants!$B$123:$B$2000, "")) | M7: =IF(D7="","", XLOOKUP(D7, Constants!$A$123:$A$2000, Constants!$B$123:$B$2000, "")) | N7: =IF(E7="","", XLOOKUP(E7, Constants!$A$123:$A$2000, Constants!$B$123:$B$2000, ""))
K8: =IF(B8="","", XLOOKUP(B8, Constants!$A$123:$A$2000, Constants!$B$123:$B$2000, "")) | L8: =IF(C8="","", XLOOKUP(C8, Constants!$A$123:$A$2000, Constants!$B$123:$B$2000, "")) | M8: =IF(D8="","", XLOOKUP(D8, Constants!$A$123:$A$2000, Constants!$B$123:$B$2000, "")) | N8: =IF(E8="","", XLOOKUP(E8, Constants!$A$123:$A$2000, Constants!$B$123:$B$2000, ""))
K9: =IF(B9="","", XLOOKUP(B9, Constants!$A$123:$A$2000, Constants!$B$123:$B$2000, "")) | L9: =IF(C9="","", XLOOKUP(C9, Constants!$A$123:$A$2000, Constants!$B$123:$B$2000, "")) | M9: =IF(D9="","", XLOOKUP(D9, Constants!$A$123:$A$2000, Constants!$B$123:$B$2000, "")) | N9: =IF(E9="","", XLOOKUP(E9, Constants!$A$123:$A$2000, Constants!$B$123:$B$2000, ""))
K10: =IF(B10="","", XLOOKUP(B10, Constants!$A$123:$A$2000, Constants!$B$123:$B$2000, "")) | L10: =IF(C10="","", XLOOKUP(C10, Constants!$A$123:$A$2000, Constants!$B$123:$B$2000, "")) | M10: =IF(D10="","", XLOOKUP(D10, Constants!$A$123:$A$2000, Constants!$B$123:$B$2000, "")) | N10: =IF(E10="","", XLOOKUP(E10, Constants!$A$123:$A$2000, Constants!$B$123:$B$2000, ""))
K11: =IF(B11="","", XLOOKUP(B11, Constants!$A$123:$A$2000, Constants!$B$123:$B$2000, "")) | L11: =IF(C11="","", XLOOKUP(C11, Constants!$A$123:$A$2000, Constants!$B$123:$B$2000, "")) | M11: =IF(D11="","", XLOOKUP(D11, Constants!$A$123:$A$2000, Constants!$B$123:$B$2000, "")) | N11: =IF(E11="","", XLOOKUP(E11, Constants!$A$123:$A$2000, Constants!$B$123:$B$2000, ""))
K12: =IF(B12="","", XLOOKUP(B12, Constants!$A$123:$A$2000, Constants!$B$123:$B$2000, "")) | L12: =IF(C12="","", XLOOKUP(C12, Constants!$A$123:$A$2000, Constants!$B$123:$B$2000, "")) | M12: =IF(D12="","", XLOOKUP(D12, Constants!$A$123:$A$2000, Constants!$B$123:$B$2000, "")) | N12: =IF(E12="","", XLOOKUP(E12, Constants!$A$123:$A$2000, Constants!$B$123:$B$2000, ""))
K13: =IF(B13="","", XLOOKUP(B13, Constants!$A$123:$A$2000, Constants!$B$123:$B$2000, "")) | L13: =IF(C13="","", XLOOKUP(C13, Constants!$A$123:$A$2000, Constants!$B$123:$B$2000, "")) | M13: =IF(D13="","", XLOOKUP(D13, Constants!$A$123:$A$2000, Constants!$B$123:$B$2000, "")) | N13: =IF(E13="","", XLOOKUP(E13, Constants!$A$123:$A$2000, Constants!$B$123:$B$2000, ""))
K14: =IF(B14="","", XLOOKUP(B14, Constants!$A$123:$A$2000, Constants!$B$123:$B$2000, "")) | L14: =IF(C14="","", XLOOKUP(C14, Constants!$A$123:$A$2000, Constants!$B$123:$B$2000, "")) | M14: =IF(D14="","", XLOOKUP(D14, Constants!$A$123:$A$2000, Constants!$B$123:$B$2000, "")) | N14: =IF(E14="","", XLOOKUP(E14, Constants!$A$123:$A$2000, Constants!$B$123:$B$2000, ""))
K15: =IF(B15="","", XLOOKUP(B15, Constants!$A$123:$A$2000, Constants!$B$123:$B$2000, "")) | L15: =IF(C15="","", XLOOKUP(C15, Constants!$A$123:$A$2000, Constants!$B$123:$B$2000, "")) | M15: =IF(D15="","", XLOOKUP(D15, Constants!$A$123:$A$2000, Constants!$B$123:$B$2000, "")) | N15: =IF(E15="","", XLOOKUP(E15, Constants!$A$123:$A$2000, Constants!$B$123:$B$2000, ""))
K16: =IF(B16="","", XLOOKUP(B16, Constants!$A$123:$A$2000, Constants!$B$123:$B$2000, "")) | L16: =IF(C16="","", XLOOKUP(C16, Constants!$A$123:$A$2000, Constants!$B$123:$B$2000, "")) | M16: =IF(D16="","", XLOOKUP(D16, Constants!$A$123:$A$2000, Constants!$B$123:$B$2000, "")) | N16: =IF(E16="","", XLOOKUP(E16, Constants!$A$123:$A$2000, Constants!$B$123:$B$2000, ""))
K17: =IF(B17="","", XLOOKUP(B17, Constants!$A$123:$A$2000, Constants!$B$123:$B$2000, "")) | L17: =IF(C17="","", XLOOKUP(C17, Constants!$A$123:$A$2000, Constants!$B$123:$B$2000, "")) | M17: =IF(D17="","", XLOOKUP(D17, Constants!$A$123:$A$2000, Constants!$B$123:$B$2000, "")) | N17: =IF(E17="","", XLOOKUP(E17, Constants!$A$123:$A$2000, Constants!$B$123:$B$2000, ""))
... K55: =IF(B55="","", XLOOKUP(B55, Constants!$A$123:$A$2000, Constants!$B$123:$B$2000, "")) | L55: =IF(C55="","", XLOOKUP(C55, Constants!$A$123:$A$2000, Constants!$B$123:$B$2000, "")) | M55: =IF(D55="","", XLOOKUP(D55, Constants!$A$123:$A$2000, Constants!$B$123:$B$2000, "")) | N55: =IF(E55="","", XLOOKUP(E55, Constants!$A$123:$A$2000, Constants!$B$123:$B$2000, ""))

Sheet INPUT_Rooms
A1: INPUT_ROOMS (Manual or App) — 1 row per room
B2: App-first mode: JobID column (A) is hidden; the app will fill JobID automatically.
A3: JobID | B3: RoomID | C3: Room Name | D3: Mode (RECT/SEG) | E3: Length_in (RECT) | F3: Width_in (RECT) | G3: WallHeight_in | H3: CeilingHeight_in | I3: CeilingSqft_override (SEG optional) | J3: BaseExclude_in (RECT) | K3: Walls Include | L3: Walls Primer | M3: Walls Topcoats | N3: Walls Prep Override | O3: Ceiling Include | P3: Ceiling Primer | Q3: Ceiling Topcoats | R3: Ceiling Prep Override | S3: Ceiling Height Surcharge $ | T3: Trim Include | U3: Trim Primer | V3: Trim Topcoats | W3: Trim Prep Override | X3: Paint Base? | Y3: Paint Crown? | Z3: Paint Window Casing? | AA3: Paint Door Casing? | AB3: Paint Doors? | AC3: Perimeter_in (calc) | AD3: WallSqft (calc) | AE3: CeilingSqft (calc) | AF3: Base_LF (calc) | AG3: Crown_LF (calc) | AH3: WallColorID (A/B/C...) | AI3: CeilingTypeID
H4: =IF($B4="","",$G4) | AC4: =IF(B4="","",IF(D4="RECT",IF(OR(E4="",F4=""),"",2*(E4+F4)),SUMIFS(INPUT_Segments!$D:$D,INPUT_Segments!$A:$A,A4,INPUT_Segments!$B:$B,B4))) | AD4: =IF(AC4="","", (AC4*G4)/144) | AE4: =IF(B4="","",IF(D4="RECT",IF(OR(E4="",F4=""),"",(E4*F4)/144),IF(I4="", "", I4))) | AF4: =IF(AC4="","",MAX(0,AC4 - SUMPRODUCT((INPUT_Openings!$A:$A=A4)*(INPUT_Openings!$B:$B=B4)*(XLOOKUP(INPUT_Openings!$C:$C,Constants!$A$30:$A$200,Constants!$C$30:$C$200,"",0))*(INPUT_Openings!$D:$D)*(XLOOKUP(INPUT_Openings!$C:$C,Constants!$A$30:$A$200,Constants!$B$30:$B$200,"",0)="Door")) - IF(D4="RECT",IF(J4="",0,J4),SUMIFS(INPUT_Segments!$E:$E,INPUT_Segments!$A:$A,A4,INPUT_Segments!$B:$B,B4)))/12) | AG4: =IF(AC4="","",AC4/12)
H5: =IF($B5="","",$G5) | AC5: =IF(B5="","",IF(D5="RECT",IF(OR(E5="",F5=""),"",2*(E5+F5)),SUMIFS(INPUT_Segments!$D:$D,INPUT_Segments!$A:$A,A5,INPUT_Segments!$B:$B,B5))) | AD5: =IF(AC5="","", (AC5*G5)/144) | AE5: =IF(B5="","",IF(D5="RECT",IF(OR(E5="",F5=""),"",(E5*F5)/144),IF(I5="", "", I5))) | AF5: =IF(AC5="","",MAX(0,AC5 - SUMPRODUCT((INPUT_Openings!$A:$A=A5)*(INPUT_Openings!$B:$B=B5)*(XLOOKUP(INPUT_Openings!$C:$C,Constants!$A$30:$A$200,Constants!$C$30:$C$200,"",0))*(INPUT_Openings!$D:$D)*(XLOOKUP(INPUT_Openings!$C:$C,Constants!$A$30:$A$200,Constants!$B$30:$B$200,"",0)="Door")) - IF(D5="RECT",IF(J5="",0,J5),SUMIFS(INPUT_Segments!$E:$E,INPUT_Segments!$A:$A,A5,INPUT_Segments!$B:$B,B5)))/12) | AG5: =IF(AC5="","",AC5/12)
H6: =IF($B6="","",$G6) | AC6: =IF(B6="","",IF(D6="RECT",IF(OR(E6="",F6=""),"",2*(E6+F6)),SUMIFS(INPUT_Segments!$D:$D,INPUT_Segments!$A:$A,A6,INPUT_Segments!$B:$B,B6))) | AD6: =IF(AC6="","", (AC6*G6)/144) | AE6: =IF(B6="","",IF(D6="RECT",IF(OR(E6="",F6=""),"",(E6*F6)/144),IF(I6="", "", I6))) | AF6: =IF(AC6="","",MAX(0,AC6 - SUMPRODUCT((INPUT_Openings!$A:$A=A6)*(INPUT_Openings!$B:$B=B6)*(XLOOKUP(INPUT_Openings!$C:$C,Constants!$A$30:$A$200,Constants!$C$30:$C$200,"",0))*(INPUT_Openings!$D:$D)*(XLOOKUP(INPUT_Openings!$C:$C,Constants!$A$30:$A$200,Constants!$B$30:$B$200,"",0)="Door")) - IF(D6="RECT",IF(J6="",0,J6),SUMIFS(INPUT_Segments!$E:$E,INPUT_Segments!$A:$A,A6,INPUT_Segments!$B:$B,B6)))/12) | AG6: =IF(AC6="","",AC6/12)
H7: =IF($B7="","",$G7) | AC7: =IF(B7="","",IF(D7="RECT",IF(OR(E7="",F7=""),"",2*(E7+F7)),SUMIFS(INPUT_Segments!$D:$D,INPUT_Segments!$A:$A,A7,INPUT_Segments!$B:$B,B7))) | AD7: =IF(AC7="","", (AC7*G7)/144) | AE7: =IF(B7="","",IF(D7="RECT",IF(OR(E7="",F7=""),"",(E7*F7)/144),IF(I7="", "", I7))) | AF7: =IF(AC7="","",MAX(0,AC7 - SUMPRODUCT((INPUT_Openings!$A:$A=A7)*(INPUT_Openings!$B:$B=B7)*(XLOOKUP(INPUT_Openings!$C:$C,Constants!$A$30:$A$200,Constants!$C$30:$C$200,"",0))*(INPUT_Openings!$D:$D)*(XLOOKUP(INPUT_Openings!$C:$C,Constants!$A$30:$A$200,Constants!$B$30:$B$200,"",0)="Door")) - IF(D7="RECT",IF(J7="",0,J7),SUMIFS(INPUT_Segments!$E:$E,INPUT_Segments!$A:$A,A7,INPUT_Segments!$B:$B,B7)))/12) | AG7: =IF(AC7="","",AC7/12)
H8: =IF($B8="","",$G8) | AC8: =IF(B8="","",IF(D8="RECT",IF(OR(E8="",F8=""),"",2*(E8+F8)),SUMIFS(INPUT_Segments!$D:$D,INPUT_Segments!$A:$A,A8,INPUT_Segments!$B:$B,B8))) | AD8: =IF(AC8="","", (AC8*G8)/144) | AE8: =IF(B8="","",IF(D8="RECT",IF(OR(E8="",F8=""),"",(E8*F8)/144),IF(I8="", "", I8))) | AF8: =IF(AC8="","",MAX(0,AC8 - SUMPRODUCT((INPUT_Openings!$A:$A=A8)*(INPUT_Openings!$B:$B=B8)*(XLOOKUP(INPUT_Openings!$C:$C,Constants!$A$30:$A$200,Constants!$C$30:$C$200,"",0))*(INPUT_Openings!$D:$D)*(XLOOKUP(INPUT_Openings!$C:$C,Constants!$A$30:$A$200,Constants!$B$30:$B$200,"",0)="Door")) - IF(D8="RECT",IF(J8="",0,J8),SUMIFS(INPUT_Segments!$E:$E,INPUT_Segments!$A:$A,A8,INPUT_Segments!$B:$B,B8)))/12) | AG8: =IF(AC8="","",AC8/12)
H9: =IF($B9="","",$G9) | AC9: =IF(B9="","",IF(D9="RECT",IF(OR(E9="",F9=""),"",2*(E9+F9)),SUMIFS(INPUT_Segments!$D:$D,INPUT_Segments!$A:$A,A9,INPUT_Segments!$B:$B,B9))) | AD9: =IF(AC9="","", (AC9*G9)/144) | AE9: =IF(B9="","",IF(D9="RECT",IF(OR(E9="",F9=""),"",(E9*F9)/144),IF(I9="", "", I9))) | AF9: =IF(AC9="","",MAX(0,AC9 - SUMPRODUCT((INPUT_Openings!$A:$A=A9)*(INPUT_Openings!$B:$B=B9)*(XLOOKUP(INPUT_Openings!$C:$C,Constants!$A$30:$A$200,Constants!$C$30:$C$200,"",0))*(INPUT_Openings!$D:$D)*(XLOOKUP(INPUT_Openings!$C:$C,Constants!$A$30:$A$200,Constants!$B$30:$B$200,"",0)="Door")) - IF(D9="RECT",IF(J9="",0,J9),SUMIFS(INPUT_Segments!$E:$E,INPUT_Segments!$A:$A,A9,INPUT_Segments!$B:$B,B9)))/12) | AG9: =IF(AC9="","",AC9/12)
H10: =IF($B10="","",$G10) | AC10: =IF(B10="","",IF(D10="RECT",IF(OR(E10="",F10=""),"",2*(E10+F10)),SUMIFS(INPUT_Segments!$D:$D,INPUT_Segments!$A:$A,A10,INPUT_Segments!$B:$B,B10))) | AD10: =IF(AC10="","", (AC10*G10)/144) | AE10: =IF(B10="","",IF(D10="RECT",IF(OR(E10="",F10=""),"",(E10*F10)/144),IF(I10="", "", I10))) | AF10: =IF(AC10="","",MAX(0,AC10 - SUMPRODUCT((INPUT_Openings!$A:$A=A10)*(INPUT_Openings!$B:$B=B10)*(XLOOKUP(INPUT_Openings!$C:$C,Constants!$A$30:$A$200,Constants!$C$30:$C$200,"",0))*(INPUT_Openings!$D:$D)*(XLOOKUP(INPUT_Openings!$C:$C,Constants!$A$30:$A$200,Constants!$B$30:$B$200,"",0)="Door")) - IF(D10="RECT",IF(J10="",0,J10),SUMIFS(INPUT_Segments!$E:$E,INPUT_Segments!$A:$A,A10,INPUT_Segments!$B:$B,B10)))/12) | AG10: =IF(AC10="","",AC10/12)
H11: =IF($B11="","",$G11) | AC11: =IF(B11="","",IF(D11="RECT",IF(OR(E11="",F11=""),"",2*(E11+F11)),SUMIFS(INPUT_Segments!$D:$D,INPUT_Segments!$A:$A,A11,INPUT_Segments!$B:$B,B11))) | AD11: =IF(AC11="","", (AC11*G11)/144) | AE11: =IF(B11="","",IF(D11="RECT",IF(OR(E11="",F11=""),"",(E11*F11)/144),IF(I11="", "", I11))) | AF11: =IF(AC11="","",MAX(0,AC11 - SUMPRODUCT((INPUT_Openings!$A:$A=A11)*(INPUT_Openings!$B:$B=B11)*(XLOOKUP(INPUT_Openings!$C:$C,Constants!$A$30:$A$200,Constants!$C$30:$C$200,"",0))*(INPUT_Openings!$D:$D)*(XLOOKUP(INPUT_Openings!$C:$C,Constants!$A$30:$A$200,Constants!$B$30:$B$200,"",0)="Door")) - IF(D11="RECT",IF(J11="",0,J11),SUMIFS(INPUT_Segments!$E:$E,INPUT_Segments!$A:$A,A11,INPUT_Segments!$B:$B,B11)))/12) | AG11: =IF(AC11="","",AC11/12)
H12: =IF($B12="","",$G12) | AC12: =IF(B12="","",IF(D12="RECT",IF(OR(E12="",F12=""),"",2*(E12+F12)),SUMIFS(INPUT_Segments!$D:$D,INPUT_Segments!$A:$A,A12,INPUT_Segments!$B:$B,B12))) | AD12: =IF(AC12="","", (AC12*G12)/144) | AE12: =IF(B12="","",IF(D12="RECT",IF(OR(E12="",F12=""),"",(E12*F12)/144),IF(I12="", "", I12))) | AF12: =IF(AC12="","",MAX(0,AC12 - SUMPRODUCT((INPUT_Openings!$A:$A=A12)*(INPUT_Openings!$B:$B=B12)*(XLOOKUP(INPUT_Openings!$C:$C,Constants!$A$30:$A$200,Constants!$C$30:$C$200,"",0))*(INPUT_Openings!$D:$D)*(XLOOKUP(INPUT_Openings!$C:$C,Constants!$A$30:$A$200,Constants!$B$30:$B$200,"",0)="Door")) - IF(D12="RECT",IF(J12="",0,J12),SUMIFS(INPUT_Segments!$E:$E,INPUT_Segments!$A:$A,A12,INPUT_Segments!$B:$B,B12)))/12) | AG12: =IF(AC12="","",AC12/12)
H13: =IF($B13="","",$G13) | AC13: =IF(B13="","",IF(D13="RECT",IF(OR(E13="",F13=""),"",2*(E13+F13)),SUMIFS(INPUT_Segments!$D:$D,INPUT_Segments!$A:$A,A13,INPUT_Segments!$B:$B,B13))) | AD13: =IF(AC13="","", (AC13*G13)/144) | AE13: =IF(B13="","",IF(D13="RECT",IF(OR(E13="",F13=""),"",(E13*F13)/144),IF(I13="", "", I13))) | AF13: =IF(AC13="","",MAX(0,AC13 - SUMPRODUCT((INPUT_Openings!$A:$A=A13)*(INPUT_Openings!$B:$B=B13)*(XLOOKUP(INPUT_Openings!$C:$C,Constants!$A$30:$A$200,Constants!$C$30:$C$200,"",0))*(INPUT_Openings!$D:$D)*(XLOOKUP(INPUT_Openings!$C:$C,Constants!$A$30:$A$200,Constants!$B$30:$B$200,"",0)="Door")) - IF(D13="RECT",IF(J13="",0,J13),SUMIFS(INPUT_Segments!$E:$E,INPUT_Segments!$A:$A,A13,INPUT_Segments!$B:$B,B13)))/12) | AG13: =IF(AC13="","",AC13/12)
H14: =IF($B14="","",$G14) | AC14: =IF(B14="","",IF(D14="RECT",IF(OR(E14="",F14=""),"",2*(E14+F14)),SUMIFS(INPUT_Segments!$D:$D,INPUT_Segments!$A:$A,A14,INPUT_Segments!$B:$B,B14))) | AD14: =IF(AC14="","", (AC14*G14)/144) | AE14: =IF(B14="","",IF(D14="RECT",IF(OR(E14="",F14=""),"",(E14*F14)/144),IF(I14="", "", I14))) | AF14: =IF(AC14="","",MAX(0,AC14 - SUMPRODUCT((INPUT_Openings!$A:$A=A14)*(INPUT_Openings!$B:$B=B14)*(XLOOKUP(INPUT_Openings!$C:$C,Constants!$A$30:$A$200,Constants!$C$30:$C$200,"",0))*(INPUT_Openings!$D:$D)*(XLOOKUP(INPUT_Openings!$C:$C,Constants!$A$30:$A$200,Constants!$B$30:$B$200,"",0)="Door")) - IF(D14="RECT",IF(J14="",0,J14),SUMIFS(INPUT_Segments!$E:$E,INPUT_Segments!$A:$A,A14,INPUT_Segments!$B:$B,B14)))/12) | AG14: =IF(AC14="","",AC14/12)
H15: =IF($B15="","",$G15) | AC15: =IF(B15="","",IF(D15="RECT",IF(OR(E15="",F15=""),"",2*(E15+F15)),SUMIFS(INPUT_Segments!$D:$D,INPUT_Segments!$A:$A,A15,INPUT_Segments!$B:$B,B15))) | AD15: =IF(AC15="","", (AC15*G15)/144) | AE15: =IF(B15="","",IF(D15="RECT",IF(OR(E15="",F15=""),"",(E15*F15)/144),IF(I15="", "", I15))) | AF15: =IF(AC15="","",MAX(0,AC15 - SUMPRODUCT((INPUT_Openings!$A:$A=A15)*(INPUT_Openings!$B:$B=B15)*(XLOOKUP(INPUT_Openings!$C:$C,Constants!$A$30:$A$200,Constants!$C$30:$C$200,"",0))*(INPUT_Openings!$D:$D)*(XLOOKUP(INPUT_Openings!$C:$C,Constants!$A$30:$A$200,Constants!$B$30:$B$200,"",0)="Door")) - IF(D15="RECT",IF(J15="",0,J15),SUMIFS(INPUT_Segments!$E:$E,INPUT_Segments!$A:$A,A15,INPUT_Segments!$B:$B,B15)))/12) | AG15: =IF(AC15="","",AC15/12)
... H83: =IF($B83="","",$G83) | AC83: =IF(B83="","",IF(D83="RECT",IF(OR(E83="",F83=""),"",2*(E83+F83)),SUMIFS(INPUT_Segments!$D:$D,INPUT_Segments!$A:$A,A83,INPUT_Segments!$B:$B,B83))) | AD83: =IF(AC83="","", (AC83*G83)/144) | AE83: =IF(B83="","",IF(D83="RECT",IF(OR(E83="",F83=""),"",(E83*F83)/144),IF(I83="", "", I83))) | AF83: =IF(AC83="","",MAX(0,AC83 - SUMPRODUCT((INPUT_Openings!$A:$A=A83)*(INPUT_Openings!$B:$B=B83)*(XLOOKUP(INPUT_Openings!$C:$C,Constants!$A$30:$A$200,Constants!$C$30:$C$200,"",0))*(INPUT_Openings!$D:$D)*(XLOOKUP(INPUT_Openings!$C:$C,Constants!$A$30:$A$200,Constants!$B$30:$B$200,"",0)="Door")) - IF(D83="RECT",IF(J83="",0,J83),SUMIFS(INPUT_Segments!$E:$E,INPUT_Segments!$A:$A,A83,INPUT_Segments!$B:$B,B83)))/12) | AG83: =IF(AC83="","",AC83/12)

Sheet INPUT_Segments
A1: INPUT_SEGMENTS (only needed for SEG rooms)
B2: App-first mode: JobID column (A) is hidden; the app will fill JobID automatically.
A3: JobID | B3: RoomID | C3: Seg# | D3: SegLen_in | E3: BaseExclude_in | F3: Notes | G3: WallLabel (optional) | H3: WallColorOverrideID (optional) | I3: Active?

Sheet INPUT_TrimLines
A1: INPUT_TRIMLINES (catalog-driven trim; app writes line items per room)
A3: Green = inputs. App writes JobID/RoomID keys. Add rows freely.
A5: JobID | B5: RoomID | C5: TrimItemID | D5: Qty | E5: PrimerMode | F5: Coats | G5: PrepLevelOverride | H5: Notes | I5: Unit (calc) | J5: PrepMins (calc) | K5: PaintMins (calc) | L5: PrimerMins (calc) | M5: TotalMins (calc) | N5: LaborHours (calc) | O5: Labor$ (calc) | P5: Material$ (calc) | Q5: Total$ w/Markup (calc)
I6: =IF(OR(A6="",C6=""),"", XLOOKUP(C6, Constants!$A:$A, Constants!$C:$C, "")) | J6: =IF(OR(A6="",C6=""),"", D6 * (IF(G6="", 1, XLOOKUP(G6, Constants!$E$10:$E$30, Constants!$F$10:$F$30, 1))) * XLOOKUP(C6, Constants!$A:$A, Constants!$D:$D, 0)) | K6: =IF(OR(A6="",C6=""),"", D6 * F6 * XLOOKUP(C6, Constants!$A:$A, Constants!$E:$E, 0)) | L6: =IF(OR(A6="",C6=""),"", IF(E6="None",0, D6 * IF(E6="Full",1,XLOOKUP("PrimerSpotFactor",Constants!$A$20:$A$40,Constants!$B$20:$B$40,0.35)) * XLOOKUP(C6, Constants!$A:$A, Constants!$F:$F, 0))) | M6: =IF(OR(A6="",C6=""),"", J6+K6+L6) | N6: =IF(OR(A6="",C6=""),"", M6/60) | O6: =IF(OR(A6="",C6=""),"", N6*(IF(XLOOKUP('Job Control'!$B$3, INPUT_JobSettings!$A:$A, INPUT_JobSettings!$F:$F, "")<>"", XLOOKUP('Job Control'!$B$3, INPUT_JobSettings!$A:$A, INPUT_JobSettings!$F:$F, ""), Summary!$B$4))) | P6: =IF(OR(A6="",C6=""),"", 0) | Q6: =IF(OR(A6="",C6=""),"", (O6+P6)*(IF(XLOOKUP('Job Control'!$B$3, INPUT_JobSettings!$A:$A, INPUT_JobSettings!$G:$G, "")<>"", XLOOKUP('Job Control'!$B$3, INPUT_JobSettings!$A:$A, INPUT_JobSettings!$G:$G, ""), Summary!$B$5)))
I7: =IF(OR(A7="",C7=""),"", XLOOKUP(C7, Constants!$A:$A, Constants!$C:$C, "")) | J7: =IF(OR(A7="",C7=""),"", D7 * (IF(G7="", 1, XLOOKUP(G7, Constants!$E$10:$E$30, Constants!$F$10:$F$30, 1))) * XLOOKUP(C7, Constants!$A:$A, Constants!$D:$D, 0)) | K7: =IF(OR(A7="",C7=""),"", D7 * F7 * XLOOKUP(C7, Constants!$A:$A, Constants!$E:$E, 0)) | L7: =IF(OR(A7="",C7=""),"", IF(E7="None",0, D7 * IF(E7="Full",1,XLOOKUP("PrimerSpotFactor",Constants!$A$20:$A$40,Constants!$B$20:$B$40,0.35)) * XLOOKUP(C7, Constants!$A:$A, Constants!$F:$F, 0))) | M7: =IF(OR(A7="",C7=""),"", J7+K7+L7) | N7: =IF(OR(A7="",C7=""),"", M7/60) | O7: =IF(OR(A7="",C7=""),"", N7*(IF(XLOOKUP('Job Control'!$B$3, INPUT_JobSettings!$A:$A, INPUT_JobSettings!$F:$F, "")<>"", XLOOKUP('Job Control'!$B$3, INPUT_JobSettings!$A:$A, INPUT_JobSettings!$F:$F, ""), Summary!$B$4))) | P7: =IF(OR(A7="",C7=""),"", 0) | Q7: =IF(OR(A7="",C7=""),"", (O7+P7)*(IF(XLOOKUP('Job Control'!$B$3, INPUT_JobSettings!$A:$A, INPUT_JobSettings!$G:$G, "")<>"", XLOOKUP('Job Control'!$B$3, INPUT_JobSettings!$A:$A, INPUT_JobSettings!$G:$G, ""), Summary!$B$5)))
I8: =IF(OR(A8="",C8=""),"", XLOOKUP(C8, Constants!$A:$A, Constants!$C:$C, "")) | J8: =IF(OR(A8="",C8=""),"", D8 * (IF(G8="", 1, XLOOKUP(G8, Constants!$E$10:$E$30, Constants!$F$10:$F$30, 1))) * XLOOKUP(C8, Constants!$A:$A, Constants!$D:$D, 0)) | K8: =IF(OR(A8="",C8=""),"", D8 * F8 * XLOOKUP(C8, Constants!$A:$A, Constants!$E:$E, 0)) | L8: =IF(OR(A8="",C8=""),"", IF(E8="None",0, D8 * IF(E8="Full",1,XLOOKUP("PrimerSpotFactor",Constants!$A$20:$A$40,Constants!$B$20:$B$40,0.35)) * XLOOKUP(C8, Constants!$A:$A, Constants!$F:$F, 0))) | M8: =IF(OR(A8="",C8=""),"", J8+K8+L8) | N8: =IF(OR(A8="",C8=""),"", M8/60) | O8: =IF(OR(A8="",C8=""),"", N8*(IF(XLOOKUP('Job Control'!$B$3, INPUT_JobSettings!$A:$A, INPUT_JobSettings!$F:$F, "")<>"", XLOOKUP('Job Control'!$B$3, INPUT_JobSettings!$A:$A, INPUT_JobSettings!$F:$F, ""), Summary!$B$4))) | P8: =IF(OR(A8="",C8=""),"", 0) | Q8: =IF(OR(A8="",C8=""),"", (O8+P8)*(IF(XLOOKUP('Job Control'!$B$3, INPUT_JobSettings!$A:$A, INPUT_JobSettings!$G:$G, "")<>"", XLOOKUP('Job Control'!$B$3, INPUT_JobSettings!$A:$A, INPUT_JobSettings!$G:$G, ""), Summary!$B$5)))
I9: =IF(OR(A9="",C9=""),"", XLOOKUP(C9, Constants!$A:$A, Constants!$C:$C, "")) | J9: =IF(OR(A9="",C9=""),"", D9 * (IF(G9="", 1, XLOOKUP(G9, Constants!$E$10:$E$30, Constants!$F$10:$F$30, 1))) * XLOOKUP(C9, Constants!$A:$A, Constants!$D:$D, 0)) | K9: =IF(OR(A9="",C9=""),"", D9 * F9 * XLOOKUP(C9, Constants!$A:$A, Constants!$E:$E, 0)) | L9: =IF(OR(A9="",C9=""),"", IF(E9="None",0, D9 * IF(E9="Full",1,XLOOKUP("PrimerSpotFactor",Constants!$A$20:$A$40,Constants!$B$20:$B$40,0.35)) * XLOOKUP(C9, Constants!$A:$A, Constants!$F:$F, 0))) | M9: =IF(OR(A9="",C9=""),"", J9+K9+L9) | N9: =IF(OR(A9="",C9=""),"", M9/60) | O9: =IF(OR(A9="",C9=""),"", N9*(IF(XLOOKUP('Job Control'!$B$3, INPUT_JobSettings!$A:$A, INPUT_JobSettings!$F:$F, "")<>"", XLOOKUP('Job Control'!$B$3, INPUT_JobSettings!$A:$A, INPUT_JobSettings!$F:$F, ""), Summary!$B$4))) | P9: =IF(OR(A9="",C9=""),"", 0) | Q9: =IF(OR(A9="",C9=""),"", (O9+P9)*(IF(XLOOKUP('Job Control'!$B$3, INPUT_JobSettings!$A:$A, INPUT_JobSettings!$G:$G, "")<>"", XLOOKUP('Job Control'!$B$3, INPUT_JobSettings!$A:$A, INPUT_JobSettings!$G:$G, ""), Summary!$B$5)))
I10: =IF(OR(A10="",C10=""),"", XLOOKUP(C10, Constants!$A:$A, Constants!$C:$C, "")) | J10: =IF(OR(A10="",C10=""),"", D10 * (IF(G10="", 1, XLOOKUP(G10, Constants!$E$10:$E$30, Constants!$F$10:$F$30, 1))) * XLOOKUP(C10, Constants!$A:$A, Constants!$D:$D, 0)) | K10: =IF(OR(A10="",C10=""),"", D10 * F10 * XLOOKUP(C10, Constants!$A:$A, Constants!$E:$E, 0)) | L10: =IF(OR(A10="",C10=""),"", IF(E10="None",0, D10 * IF(E10="Full",1,XLOOKUP("PrimerSpotFactor",Constants!$A$20:$A$40,Constants!$B$20:$B$40,0.35)) * XLOOKUP(C10, Constants!$A:$A, Constants!$F:$F, 0))) | M10: =IF(OR(A10="",C10=""),"", J10+K10+L10) | N10: =IF(OR(A10="",C10=""),"", M10/60) | O10: =IF(OR(A10="",C10=""),"", N10*(IF(XLOOKUP('Job Control'!$B$3, INPUT_JobSettings!$A:$A, INPUT_JobSettings!$F:$F, "")<>"", XLOOKUP('Job Control'!$B$3, INPUT_JobSettings!$A:$A, INPUT_JobSettings!$F:$F, ""), Summary!$B$4))) | P10: =IF(OR(A10="",C10=""),"", 0) | Q10: =IF(OR(A10="",C10=""),"", (O10+P10)*(IF(XLOOKUP('Job Control'!$B$3, INPUT_JobSettings!$A:$A, INPUT_JobSettings!$G:$G, "")<>"", XLOOKUP('Job Control'!$B$3, INPUT_JobSettings!$A:$A, INPUT_JobSettings!$G:$G, ""), Summary!$B$5)))
I11: =IF(OR(A11="",C11=""),"", XLOOKUP(C11, Constants!$A:$A, Constants!$C:$C, "")) | J11: =IF(OR(A11="",C11=""),"", D11 * (IF(G11="", 1, XLOOKUP(G11, Constants!$E$10:$E$30, Constants!$F$10:$F$30, 1))) * XLOOKUP(C11, Constants!$A:$A, Constants!$D:$D, 0)) | K11: =IF(OR(A11="",C11=""),"", D11 * F11 * XLOOKUP(C11, Constants!$A:$A, Constants!$E:$E, 0)) | L11: =IF(OR(A11="",C11=""),"", IF(E11="None",0, D11 * IF(E11="Full",1,XLOOKUP("PrimerSpotFactor",Constants!$A$20:$A$40,Constants!$B$20:$B$40,0.35)) * XLOOKUP(C11, Constants!$A:$A, Constants!$F:$F, 0))) | M11: =IF(OR(A11="",C11=""),"", J11+K11+L11) | N11: =IF(OR(A11="",C11=""),"", M11/60) | O11: =IF(OR(A11="",C11=""),"", N11*(IF(XLOOKUP('Job Control'!$B$3, INPUT_JobSettings!$A:$A, INPUT_JobSettings!$F:$F, "")<>"", XLOOKUP('Job Control'!$B$3, INPUT_JobSettings!$A:$A, INPUT_JobSettings!$F:$F, ""), Summary!$B$4))) | P11: =IF(OR(A11="",C11=""),"", 0) | Q11: =IF(OR(A11="",C11=""),"", (O11+P11)*(IF(XLOOKUP('Job Control'!$B$3, INPUT_JobSettings!$A:$A, INPUT_JobSettings!$G:$G, "")<>"", XLOOKUP('Job Control'!$B$3, INPUT_JobSettings!$A:$A, INPUT_JobSettings!$G:$G, ""), Summary!$B$5)))
I12: =IF(OR(A12="",C12=""),"", XLOOKUP(C12, Constants!$A:$A, Constants!$C:$C, "")) | J12: =IF(OR(A12="",C12=""),"", D12 * (IF(G12="", 1, XLOOKUP(G12, Constants!$E$10:$E$30, Constants!$F$10:$F$30, 1))) * XLOOKUP(C12, Constants!$A:$A, Constants!$D:$D, 0)) | K12: =IF(OR(A12="",C12=""),"", D12 * F12 * XLOOKUP(C12, Constants!$A:$A, Constants!$E:$E, 0)) | L12: =IF(OR(A12="",C12=""),"", IF(E12="None",0, D12 * IF(E12="Full",1,XLOOKUP("PrimerSpotFactor",Constants!$A$20:$A$40,Constants!$B$20:$B$40,0.35)) * XLOOKUP(C12, Constants!$A:$A, Constants!$F:$F, 0))) | M12: =IF(OR(A12="",C12=""),"", J12+K12+L12) | N12: =IF(OR(A12="",C12=""),"", M12/60) | O12: =IF(OR(A12="",C12=""),"", N12*(IF(XLOOKUP('Job Control'!$B$3, INPUT_JobSettings!$A:$A, INPUT_JobSettings!$F:$F, "")<>"", XLOOKUP('Job Control'!$B$3, INPUT_JobSettings!$A:$A, INPUT_JobSettings!$F:$F, ""), Summary!$B$4))) | P12: =IF(OR(A12="",C12=""),"", 0) | Q12: =IF(OR(A12="",C12=""),"", (O12+P12)*(IF(XLOOKUP('Job Control'!$B$3, INPUT_JobSettings!$A:$A, INPUT_JobSettings!$G:$G, "")<>"", XLOOKUP('Job Control'!$B$3, INPUT_JobSettings!$A:$A, INPUT_JobSettings!$G:$G, ""), Summary!$B$5)))
I13: =IF(OR(A13="",C13=""),"", XLOOKUP(C13, Constants!$A:$A, Constants!$C:$C, "")) | J13: =IF(OR(A13="",C13=""),"", D13 * (IF(G13="", 1, XLOOKUP(G13, Constants!$E$10:$E$30, Constants!$F$10:$F$30, 1))) * XLOOKUP(C13, Constants!$A:$A, Constants!$D:$D, 0)) | K13: =IF(OR(A13="",C13=""),"", D13 * F13 * XLOOKUP(C13, Constants!$A:$A, Constants!$E:$E, 0)) | L13: =IF(OR(A13="",C13=""),"", IF(E13="None",0, D13 * IF(E13="Full",1,XLOOKUP("PrimerSpotFactor",Constants!$A$20:$A$40,Constants!$B$20:$B$40,0.35)) * XLOOKUP(C13, Constants!$A:$A, Constants!$F:$F, 0))) | M13: =IF(OR(A13="",C13=""),"", J13+K13+L13) | N13: =IF(OR(A13="",C13=""),"", M13/60) | O13: =IF(OR(A13="",C13=""),"", N13*(IF(XLOOKUP('Job Control'!$B$3, INPUT_JobSettings!$A:$A, INPUT_JobSettings!$F:$F, "")<>"", XLOOKUP('Job Control'!$B$3, INPUT_JobSettings!$A:$A, INPUT_JobSettings!$F:$F, ""), Summary!$B$4))) | P13: =IF(OR(A13="",C13=""),"", 0) | Q13: =IF(OR(A13="",C13=""),"", (O13+P13)*(IF(XLOOKUP('Job Control'!$B$3, INPUT_JobSettings!$A:$A, INPUT_JobSettings!$G:$G, "")<>"", XLOOKUP('Job Control'!$B$3, INPUT_JobSettings!$A:$A, INPUT_JobSettings!$G:$G, ""), Summary!$B$5)))
I14: =IF(OR(A14="",C14=""),"", XLOOKUP(C14, Constants!$A:$A, Constants!$C:$C, "")) | J14: =IF(OR(A14="",C14=""),"", D14 * (IF(G14="", 1, XLOOKUP(G14, Constants!$E$10:$E$30, Constants!$F$10:$F$30, 1))) * XLOOKUP(C14, Constants!$A:$A, Constants!$D:$D, 0)) | K14: =IF(OR(A14="",C14=""),"", D14 * F14 * XLOOKUP(C14, Constants!$A:$A, Constants!$E:$E, 0)) | L14: =IF(OR(A14="",C14=""),"", IF(E14="None",0, D14 * IF(E14="Full",1,XLOOKUP("PrimerSpotFactor",Constants!$A$20:$A$40,Constants!$B$20:$B$40,0.35)) * XLOOKUP(C14, Constants!$A:$A, Constants!$F:$F, 0))) | M14: =IF(OR(A14="",C14=""),"", J14+K14+L14) | N14: =IF(OR(A14="",C14=""),"", M14/60) | O14: =IF(OR(A14="",C14=""),"", N14*(IF(XLOOKUP('Job Control'!$B$3, INPUT_JobSettings!$A:$A, INPUT_JobSettings!$F:$F, "")<>"", XLOOKUP('Job Control'!$B$3, INPUT_JobSettings!$A:$A, INPUT_JobSettings!$F:$F, ""), Summary!$B$4))) | P14: =IF(OR(A14="",C14=""),"", 0) | Q14: =IF(OR(A14="",C14=""),"", (O14+P14)*(IF(XLOOKUP('Job Control'!$B$3, INPUT_JobSettings!$A:$A, INPUT_JobSettings!$G:$G, "")<>"", XLOOKUP('Job Control'!$B$3, INPUT_JobSettings!$A:$A, INPUT_JobSettings!$G:$G, ""), Summary!$B$5)))
I15: =IF(OR(A15="",C15=""),"", XLOOKUP(C15, Constants!$A:$A, Constants!$C:$C, "")) | J15: =IF(OR(A15="",C15=""),"", D15 * (IF(G15="", 1, XLOOKUP(G15, Constants!$E$10:$E$30, Constants!$F$10:$F$30, 1))) * XLOOKUP(C15, Constants!$A:$A, Constants!$D:$D, 0)) | K15: =IF(OR(A15="",C15=""),"", D15 * F15 * XLOOKUP(C15, Constants!$A:$A, Constants!$E:$E, 0)) | L15: =IF(OR(A15="",C15=""),"", IF(E15="None",0, D15 * IF(E15="Full",1,XLOOKUP("PrimerSpotFactor",Constants!$A$20:$A$40,Constants!$B$20:$B$40,0.35)) * XLOOKUP(C15, Constants!$A:$A, Constants!$F:$F, 0))) | M15: =IF(OR(A15="",C15=""),"", J15+K15+L15) | N15: =IF(OR(A15="",C15=""),"", M15/60) | O15: =IF(OR(A15="",C15=""),"", N15*(IF(XLOOKUP('Job Control'!$B$3, INPUT_JobSettings!$A:$A, INPUT_JobSettings!$F:$F, "")<>"", XLOOKUP('Job Control'!$B$3, INPUT_JobSettings!$A:$A, INPUT_JobSettings!$F:$F, ""), Summary!$B$4))) | P15: =IF(OR(A15="",C15=""),"", 0) | Q15: =IF(OR(A15="",C15=""),"", (O15+P15)*(IF(XLOOKUP('Job Control'!$B$3, INPUT_JobSettings!$A:$A, INPUT_JobSettings!$G:$G, "")<>"", XLOOKUP('Job Control'!$B$3, INPUT_JobSettings!$A:$A, INPUT_JobSettings!$G:$G, ""), Summary!$B$5)))
I16: =IF(OR(A16="",C16=""),"", XLOOKUP(C16, Constants!$A:$A, Constants!$C:$C, "")) | J16: =IF(OR(A16="",C16=""),"", D16 * (IF(G16="", 1, XLOOKUP(G16, Constants!$E$10:$E$30, Constants!$F$10:$F$30, 1))) * XLOOKUP(C16, Constants!$A:$A, Constants!$D:$D, 0)) | K16: =IF(OR(A16="",C16=""),"", D16 * F16 * XLOOKUP(C16, Constants!$A:$A, Constants!$E:$E, 0)) | L16: =IF(OR(A16="",C16=""),"", IF(E16="None",0, D16 * IF(E16="Full",1,XLOOKUP("PrimerSpotFactor",Constants!$A$20:$A$40,Constants!$B$20:$B$40,0.35)) * XLOOKUP(C16, Constants!$A:$A, Constants!$F:$F, 0))) | M16: =IF(OR(A16="",C16=""),"", J16+K16+L16) | N16: =IF(OR(A16="",C16=""),"", M16/60) | O16: =IF(OR(A16="",C16=""),"", N16*(IF(XLOOKUP('Job Control'!$B$3, INPUT_JobSettings!$A:$A, INPUT_JobSettings!$F:$F, "")<>"", XLOOKUP('Job Control'!$B$3, INPUT_JobSettings!$A:$A, INPUT_JobSettings!$F:$F, ""), Summary!$B$4))) | P16: =IF(OR(A16="",C16=""),"", 0) | Q16: =IF(OR(A16="",C16=""),"", (O16+P16)*(IF(XLOOKUP('Job Control'!$B$3, INPUT_JobSettings!$A:$A, INPUT_JobSettings!$G:$G, "")<>"", XLOOKUP('Job Control'!$B$3, INPUT_JobSettings!$A:$A, INPUT_JobSettings!$G:$G, ""), Summary!$B$5)))
I17: =IF(OR(A17="",C17=""),"", XLOOKUP(C17, Constants!$A:$A, Constants!$C:$C, "")) | J17: =IF(OR(A17="",C17=""),"", D17 * (IF(G17="", 1, XLOOKUP(G17, Constants!$E$10:$E$30, Constants!$F$10:$F$30, 1))) * XLOOKUP(C17, Constants!$A:$A, Constants!$D:$D, 0)) | K17: =IF(OR(A17="",C17=""),"", D17 * F17 * XLOOKUP(C17, Constants!$A:$A, Constants!$E:$E, 0)) | L17: =IF(OR(A17="",C17=""),"", IF(E17="None",0, D17 * IF(E17="Full",1,XLOOKUP("PrimerSpotFactor",Constants!$A$20:$A$40,Constants!$B$20:$B$40,0.35)) * XLOOKUP(C17, Constants!$A:$A, Constants!$F:$F, 0))) | M17: =IF(OR(A17="",C17=""),"", J17+K17+L17) | N17: =IF(OR(A17="",C17=""),"", M17/60) | O17: =IF(OR(A17="",C17=""),"", N17*(IF(XLOOKUP('Job Control'!$B$3, INPUT_JobSettings!$A:$A, INPUT_JobSettings!$F:$F, "")<>"", XLOOKUP('Job Control'!$B$3, INPUT_JobSettings!$A:$A, INPUT_JobSettings!$F:$F, ""), Summary!$B$4))) | P17: =IF(OR(A17="",C17=""),"", 0) | Q17: =IF(OR(A17="",C17=""),"", (O17+P17)*(IF(XLOOKUP('Job Control'!$B$3, INPUT_JobSettings!$A:$A, INPUT_JobSettings!$G:$G, "")<>"", XLOOKUP('Job Control'!$B$3, INPUT_JobSettings!$A:$A, INPUT_JobSettings!$G:$G, ""), Summary!$B$5)))
... I305: =IF(OR(A305="",C305=""),"", XLOOKUP(C305, Constants!$A:$A, Constants!$C:$C, "")) | J305: =IF(OR(A305="",C305=""),"", D305 * (IF(G305="", 1, XLOOKUP(G305, Constants!$E$10:$E$30, Constants!$F$10:$F$30, 1))) * XLOOKUP(C305, Constants!$A:$A, Constants!$D:$D, 0)) | K305: =IF(OR(A305="",C305=""),"", D305 * F305 * XLOOKUP(C305, Constants!$A:$A, Constants!$E:$E, 0)) | L305: =IF(OR(A305="",C305=""),"", IF(E305="None",0, D305 * IF(E305="Full",1,XLOOKUP("PrimerSpotFactor",Constants!$A$20:$A$40,Constants!$B$20:$B$40,0.35)) * XLOOKUP(C305, Constants!$A:$A, Constants!$F:$F, 0))) | M305: =IF(OR(A305="",C305=""),"", J305+K305+L305) | N305: =IF(OR(A305="",C305=""),"", M305/60) | O305: =IF(OR(A305="",C305=""),"", N305*(IF(XLOOKUP('Job Control'!$B$3, INPUT_JobSettings!$A:$A, INPUT_JobSettings!$F:$F, "")<>"", XLOOKUP('Job Control'!$B$3, INPUT_JobSettings!$A:$A, INPUT_JobSettings!$F:$F, ""), Summary!$B$4))) | P305: =IF(OR(A305="",C305=""),"", 0) | Q305: =IF(OR(A305="",C305=""),"", (O305+P305)*(IF(XLOOKUP('Job Control'!$B$3, INPUT_JobSettings!$A:$A, INPUT_JobSettings!$G:$G, "")<>"", XLOOKUP('Job Control'!$B$3, INPUT_JobSettings!$A:$A, INPUT_JobSettings!$G:$G, ""), Summary!$B$5)))

Sheet INPUT_Openings
A1: INPUT_OPENINGS (counts drive cut-in mins + casing LF)
B2: App-first mode: JobID column (A) is hidden; the app will fill JobID automatically.
A3: JobID | B3: RoomID | C3: OpeningType | D3: Qty | E3: Category (calc) | F3: CutInMins_each (calc)
E4: =IF(C4="","",XLOOKUP(C4,Constants!$A$30:$A$200,Constants!$B$30:$B$200,"",0)) | F4: =IF(C4="","",XLOOKUP(C4,Constants!$A$30:$A$200,Constants!$F$30:$F$200,"",0))
E5: =IF(C5="","",XLOOKUP(C5,Constants!$A$30:$A$200,Constants!$B$30:$B$200,"",0)) | F5: =IF(C5="","",XLOOKUP(C5,Constants!$A$30:$A$200,Constants!$F$30:$F$200,"",0))
E6: =IF(C6="","",XLOOKUP(C6,Constants!$A$30:$A$200,Constants!$B$30:$B$200,"",0)) | F6: =IF(C6="","",XLOOKUP(C6,Constants!$A$30:$A$200,Constants!$F$30:$F$200,"",0))
E7: =IF(C7="","",XLOOKUP(C7,Constants!$A$30:$A$200,Constants!$B$30:$B$200,"",0)) | F7: =IF(C7="","",XLOOKUP(C7,Constants!$A$30:$A$200,Constants!$F$30:$F$200,"",0))
E8: =IF(C8="","",XLOOKUP(C8,Constants!$A$30:$A$200,Constants!$B$30:$B$200,"",0)) | F8: =IF(C8="","",XLOOKUP(C8,Constants!$A$30:$A$200,Constants!$F$30:$F$200,"",0))
E9: =IF(C9="","",XLOOKUP(C9,Constants!$A$30:$A$200,Constants!$B$30:$B$200,"",0)) | F9: =IF(C9="","",XLOOKUP(C9,Constants!$A$30:$A$200,Constants!$F$30:$F$200,"",0))
E10: =IF(C10="","",XLOOKUP(C10,Constants!$A$30:$A$200,Constants!$B$30:$B$200,"",0)) | F10: =IF(C10="","",XLOOKUP(C10,Constants!$A$30:$A$200,Constants!$F$30:$F$200,"",0))
E11: =IF(C11="","",XLOOKUP(C11,Constants!$A$30:$A$200,Constants!$B$30:$B$200,"",0)) | F11: =IF(C11="","",XLOOKUP(C11,Constants!$A$30:$A$200,Constants!$F$30:$F$200,"",0))
E12: =IF(C12="","",XLOOKUP(C12,Constants!$A$30:$A$200,Constants!$B$30:$B$200,"",0)) | F12: =IF(C12="","",XLOOKUP(C12,Constants!$A$30:$A$200,Constants!$F$30:$F$200,"",0))
E13: =IF(C13="","",XLOOKUP(C13,Constants!$A$30:$A$200,Constants!$B$30:$B$200,"",0)) | F13: =IF(C13="","",XLOOKUP(C13,Constants!$A$30:$A$200,Constants!$F$30:$F$200,"",0))
E14: =IF(C14="","",XLOOKUP(C14,Constants!$A$30:$A$200,Constants!$B$30:$B$200,"",0)) | F14: =IF(C14="","",XLOOKUP(C14,Constants!$A$30:$A$200,Constants!$F$30:$F$200,"",0))
E15: =IF(C15="","",XLOOKUP(C15,Constants!$A$30:$A$200,Constants!$B$30:$B$200,"",0)) | F15: =IF(C15="","",XLOOKUP(C15,Constants!$A$30:$A$200,Constants!$F$30:$F$200,"",0))
... E403: =IF(C403="","",XLOOKUP(C403,Constants!$A$30:$A$200,Constants!$B$30:$B$200,"",0)) | F403: =IF(C403="","",XLOOKUP(C403,Constants!$A$30:$A$200,Constants!$F$30:$F$200,"",0))

Sheet INPUT_Doors
A1: INPUT_DOORS (door type + qty + sides multiplier)
B2: App-first mode: JobID column (A) is hidden; the app will fill JobID automatically.
A3: JobID | B3: RoomID | C3: DoorType | D3: Qty | E3: Sides (0.5/1) | F3: PrepMins_side (calc) | G3: PaintMins_coat_side (calc)
F4: =IF(C4="","",XLOOKUP(C4,Constants!$H$30:$H$200,Constants!$I$30:$I$200,"",0)) | G4: =IF(C4="","",XLOOKUP(C4,Constants!$H$30:$H$200,Constants!$J$30:$J$200,"",0))
F5: =IF(C5="","",XLOOKUP(C5,Constants!$H$30:$H$200,Constants!$I$30:$I$200,"",0)) | G5: =IF(C5="","",XLOOKUP(C5,Constants!$H$30:$H$200,Constants!$J$30:$J$200,"",0))
F6: =IF(C6="","",XLOOKUP(C6,Constants!$H$30:$H$200,Constants!$I$30:$I$200,"",0)) | G6: =IF(C6="","",XLOOKUP(C6,Constants!$H$30:$H$200,Constants!$J$30:$J$200,"",0))
F7: =IF(C7="","",XLOOKUP(C7,Constants!$H$30:$H$200,Constants!$I$30:$I$200,"",0)) | G7: =IF(C7="","",XLOOKUP(C7,Constants!$H$30:$H$200,Constants!$J$30:$J$200,"",0))
F8: =IF(C8="","",XLOOKUP(C8,Constants!$H$30:$H$200,Constants!$I$30:$I$200,"",0)) | G8: =IF(C8="","",XLOOKUP(C8,Constants!$H$30:$H$200,Constants!$J$30:$J$200,"",0))
F9: =IF(C9="","",XLOOKUP(C9,Constants!$H$30:$H$200,Constants!$I$30:$I$200,"",0)) | G9: =IF(C9="","",XLOOKUP(C9,Constants!$H$30:$H$200,Constants!$J$30:$J$200,"",0))
F10: =IF(C10="","",XLOOKUP(C10,Constants!$H$30:$H$200,Constants!$I$30:$I$200,"",0)) | G10: =IF(C10="","",XLOOKUP(C10,Constants!$H$30:$H$200,Constants!$J$30:$J$200,"",0))
F11: =IF(C11="","",XLOOKUP(C11,Constants!$H$30:$H$200,Constants!$I$30:$I$200,"",0)) | G11: =IF(C11="","",XLOOKUP(C11,Constants!$H$30:$H$200,Constants!$J$30:$J$200,"",0))
F12: =IF(C12="","",XLOOKUP(C12,Constants!$H$30:$H$200,Constants!$I$30:$I$200,"",0)) | G12: =IF(C12="","",XLOOKUP(C12,Constants!$H$30:$H$200,Constants!$J$30:$J$200,"",0))
F13: =IF(C13="","",XLOOKUP(C13,Constants!$H$30:$H$200,Constants!$I$30:$I$200,"",0)) | G13: =IF(C13="","",XLOOKUP(C13,Constants!$H$30:$H$200,Constants!$J$30:$J$200,"",0))
F14: =IF(C14="","",XLOOKUP(C14,Constants!$H$30:$H$200,Constants!$I$30:$I$200,"",0)) | G14: =IF(C14="","",XLOOKUP(C14,Constants!$H$30:$H$200,Constants!$J$30:$J$200,"",0))
F15: =IF(C15="","",XLOOKUP(C15,Constants!$H$30:$H$200,Constants!$I$30:$I$200,"",0)) | G15: =IF(C15="","",XLOOKUP(C15,Constants!$H$30:$H$200,Constants!$J$30:$J$200,"",0))
... F303: =IF(C303="","",XLOOKUP(C303,Constants!$H$30:$H$200,Constants!$I$30:$I$200,"",0)) | G303: =IF(C303="","",XLOOKUP(C303,Constants!$H$30:$H$200,Constants!$J$30:$J$200,"",0))

Sheet INPUT_PreJobTrips
A1: INPUT_PREJOB_TRIPS (separate from main rounding)
B2: App-first mode: JobID column (A) is hidden; the app will fill JobID automatically.
A3: JobID | B3: Category (Walls/Trim/Ceiling/Other) | C3: Trip Name | D3: Qty | E3: Hours_each | F3: LaborRate | G3: Markup | H3: Total (calc) | I3: Notes | J3: Active?
H4: =D4*E4*F4*G4
F5: =XLOOKUP("LaborRate",Constants!$A$10:$A$60,Constants!$B$10:$B$60) | G5: =XLOOKUP("Markup",Constants!$A$10:$A$60,Constants!$B$10:$B$60) | H5: =IF(OR(D5="",E5=""),"", D5*E5*F5*G5)
F6: =XLOOKUP("LaborRate",Constants!$A$10:$A$60,Constants!$B$10:$B$60) | G6: =XLOOKUP("Markup",Constants!$A$10:$A$60,Constants!$B$10:$B$60) | H6: =IF(OR(D6="",E6=""),"", D6*E6*F6*G6)
F7: =XLOOKUP("LaborRate",Constants!$A$10:$A$60,Constants!$B$10:$B$60) | G7: =XLOOKUP("Markup",Constants!$A$10:$A$60,Constants!$B$10:$B$60) | H7: =IF(OR(D7="",E7=""),"", D7*E7*F7*G7)
F8: =XLOOKUP("LaborRate",Constants!$A$10:$A$60,Constants!$B$10:$B$60) | G8: =XLOOKUP("Markup",Constants!$A$10:$A$60,Constants!$B$10:$B$60) | H8: =IF(OR(D8="",E8=""),"", D8*E8*F8*G8)
F9: =XLOOKUP("LaborRate",Constants!$A$10:$A$60,Constants!$B$10:$B$60) | G9: =XLOOKUP("Markup",Constants!$A$10:$A$60,Constants!$B$10:$B$60) | H9: =IF(OR(D9="",E9=""),"", D9*E9*F9*G9)
F10: =XLOOKUP("LaborRate",Constants!$A$10:$A$60,Constants!$B$10:$B$60) | G10: =XLOOKUP("Markup",Constants!$A$10:$A$60,Constants!$B$10:$B$60) | H10: =IF(OR(D10="",E10=""),"", D10*E10*F10*G10)
F11: =XLOOKUP("LaborRate",Constants!$A$10:$A$60,Constants!$B$10:$B$60) | G11: =XLOOKUP("Markup",Constants!$A$10:$A$60,Constants!$B$10:$B$60) | H11: =IF(OR(D11="",E11=""),"", D11*E11*F11*G11)
F12: =XLOOKUP("LaborRate",Constants!$A$10:$A$60,Constants!$B$10:$B$60) | G12: =XLOOKUP("Markup",Constants!$A$10:$A$60,Constants!$B$10:$B$60) | H12: =IF(OR(D12="",E12=""),"", D12*E12*F12*G12)
F13: =XLOOKUP("LaborRate",Constants!$A$10:$A$60,Constants!$B$10:$B$60) | G13: =XLOOKUP("Markup",Constants!$A$10:$A$60,Constants!$B$10:$B$60) | H13: =IF(OR(D13="",E13=""),"", D13*E13*F13*G13)
F14: =XLOOKUP("LaborRate",Constants!$A$10:$A$60,Constants!$B$10:$B$60) | G14: =XLOOKUP("Markup",Constants!$A$10:$A$60,Constants!$B$10:$B$60) | H14: =IF(OR(D14="",E14=""),"", D14*E14*F14*G14)
F15: =XLOOKUP("LaborRate",Constants!$A$10:$A$60,Constants!$B$10:$B$60) | G15: =XLOOKUP("Markup",Constants!$A$10:$A$60,Constants!$B$10:$B$60) | H15: =IF(OR(D15="",E15=""),"", D15*E15*F15*G15)
F16: =XLOOKUP("LaborRate",Constants!$A$10:$A$60,Constants!$B$10:$B$60) | G16: =XLOOKUP("Markup",Constants!$A$10:$A$60,Constants!$B$10:$B$60) | H16: =IF(OR(D16="",E16=""),"", D16*E16*F16*G16)
... F203: =XLOOKUP("LaborRate",Constants!$A$10:$A$60,Constants!$B$10:$B$60) | G203: =XLOOKUP("Markup",Constants!$A$10:$A$60,Constants!$B$10:$B$60) | H203: =IF(OR(D203="",E203=""),"", D203*E203*F203*G203)

Sheet INPUT_Rollers
A3: JobID | B3: Scope (Wall/Ceiling) | C3: WallColorID (Walls only) | D3: RollerSize_in (9/14/18) | E3: CoversQty | F3: PriceEach (calc) | G3: Total$ (calc) | H3: Notes | I3: Active?

Sheet ENGINE_Walls
A1: WALLS ENGINE (reads INPUT_* tables)
A3: Scope Settings
A4: JobID (filter) | B4: ='Job Control'!$B$3
A5: Default Prep Level | B5: Light
A6: Labor Rate ($/hr) | B6: =XLOOKUP("LaborRate",Constants!$A$10:$A$60,Constants!$B$10:$B$60)
A7: Markup | B7: =XLOOKUP("Markup",Constants!$A$10:$A$60,Constants!$B$10:$B$60)
A10: RoomID | B10: Room Name | C10: Include | D10: WallSqft | E10: Primer | F10: Topcoats | G10: PrepLevelUsed | H10: PrepMins | I10: PaintMins | J10: PrimerMins | K10: OpeningsCutInMins | L10: Paint_gal (calc) | M10: Primer_gal (calc) | N10: Material$ (calc) | O10: TotalMins | P10: LaborHours | Q10: Labor$ | R10: Total$ w/Markup | S10: WallColorID (room default)
A11: =IFERROR(INDEX(FILTER(INPUT_Rooms!$B$4:$B$83, INPUT_Rooms!$A$4:$A$83=$B$4, INPUT_Rooms!$K$4:$K$83="Y"), 1), "") | B11: =IF(A11="","", XLOOKUP(A11, FILTER(INPUT_Rooms!$B$4:$B$83, INPUT_Rooms!$A$4:$A$83=$B$4), FILTER(INPUT_Rooms!$C$4:$C$83, INPUT_Rooms!$A$4:$A$83=$B$4), "")) | C11: =IF(A11="","", "Y") | D11: =IF(A11="","", XLOOKUP(A11, INPUT_Rooms!$B:$B, INPUT_Rooms!$AD:$AD, "")) | E11: =IF(A11="","", XLOOKUP(A11, INPUT_Rooms!$B:$B, INPUT_Rooms!$L:$L, "")) | F11: =IF(A11="","", XLOOKUP(A11, INPUT_Rooms!$B:$B, INPUT_Rooms!$M:$M, "")) | G11: =IF(A11="","", IF(XLOOKUP(A11, INPUT_Rooms!$B:$B, INPUT_Rooms!$N:$N, "")="", $B$5, XLOOKUP(A11, INPUT_Rooms!$B:$B, INPUT_Rooms!$N:$N, ""))) | H11: =IF(A11="","", D11*XLOOKUP("PrepMinsPerSqft",Constants!$A$20:$A$40,Constants!$B$20:$B$40)*XLOOKUP(G11,Constants!$E$10:$E$30,Constants!$F$10:$F$30)) | I11: =IF(A11="","", D11*XLOOKUP("PaintMinsPerSqftPerCoat",Constants!$A$20:$A$40,Constants!$B$20:$B$40)*F11) | J11: =IF(A11="","", IF(E11="Full", D11*XLOOKUP("PrimerFullMinsPerSqft",Constants!$A$20:$A$40,Constants!$B$20:$B$40), IF(E11="Spot", D11*XLOOKUP("PrimerFullMinsPerSqft",Constants!$A$20:$A$40,Constants!$B$20:$B$40)*XLOOKUP("PrimerSpotFactor",Constants!$A$20:$A$40,Constants!$B$20:$B$40), 0))) | K11: =IF(A11="","", SUMPRODUCT((INPUT_Openings!$A:$A=$B$4)*(INPUT_Openings!$B:$B=A11)*(INPUT_Openings!$D:$D)*INPUT_Openings!$F:$F)) | L11: =IF($A11="","",IF($D11="", "",IFERROR(CEILING( ($D11*$F11) / IFERROR(XLOOKUP(XLOOKUP('Job Control'!$B$3, INPUT_JobSettings!$A:$A, INPUT_JobSettings!$B:$B, ""), Constants!$A:$A, Constants!$D:$D, ""), ""), 0.25), ""))) | M11: =IF($A11="","",IF($E11="None",0,IF($D11="", "",IFERROR(CEILING( ($D11*IF($E11="Full",1, XLOOKUP("PrimerSpotFactor",Constants!$A$10:$A$60,Constants!$B$10:$B$60))) / IFERROR(XLOOKUP(XLOOKUP('Job Control'!$B$3, INPUT_JobSettings!$A:$A, INPUT_JobSettings!$E:$E, ""), Constants!$A:$A, Constants!$D:$D, ""), ""), 0.25), "")))) | N11: =IF($A11="","",IFERROR($L11*IFERROR(XLOOKUP(XLOOKUP('Job Control'!$B$3, INPUT_JobSettings!$A:$A, INPUT_JobSettings!$B:$B, ""), Constants!$A:$A, Constants!$C:$C, 0), 0) + $M11*IFERROR(XLOOKUP(XLOOKUP('Job Control'!$B$3, INPUT_JobSettings!$A:$A, INPUT_JobSettings!$E:$E, ""), Constants!$A:$A, Constants!$C:$C, 0), 0),0)) | O11: =IF($A11="","", SUM($H11:$K11)) | P11: =IF($A11="","", $O11/60) | Q11: =IF($A11="","", $P11*IFERROR(IF(XLOOKUP('Job Control'!$B$3, INPUT_JobSettings!$A:$A, INPUT_JobSettings!$F:$F, "")<>"", XLOOKUP('Job Control'!$B$3, INPUT_JobSettings!$A:$A, INPUT_JobSettings!$F:$F, ""), $B$6), $B$6)) | R11: =IF($A11="","", ($Q11+$N11)*IFERROR(IF(XLOOKUP('Job Control'!$B$3, INPUT_JobSettings!$A:$A, INPUT_JobSettings!$G:$G, "")<>"", XLOOKUP('Job Control'!$B$3, INPUT_JobSettings!$A:$A, INPUT_JobSettings!$G:$G, ""), $B$7), $B$7)) | S11: =IF($A11="","", XLOOKUP($A11, INPUT_Rooms!$B:$B, INPUT_Rooms!$AH:$AH, ""))
A12: =IFERROR(INDEX(FILTER(INPUT_Rooms!$B$4:$B$83, INPUT_Rooms!$A$4:$A$83=$B$4, INPUT_Rooms!$K$4:$K$83="Y"), 2), "") | B12: =IF(A12="","", XLOOKUP(A12, FILTER(INPUT_Rooms!$B$4:$B$83, INPUT_Rooms!$A$4:$A$83=$B$4), FILTER(INPUT_Rooms!$C$4:$C$83, INPUT_Rooms!$A$4:$A$83=$B$4), "")) | C12: =IF(A12="","", "Y") | D12: =IF(A12="","", XLOOKUP(A12, INPUT_Rooms!$B:$B, INPUT_Rooms!$AD:$AD, "")) | E12: =IF(A12="","", XLOOKUP(A12, INPUT_Rooms!$B:$B, INPUT_Rooms!$L:$L, "")) | F12: =IF(A12="","", XLOOKUP(A12, INPUT_Rooms!$B:$B, INPUT_Rooms!$M:$M, "")) | G12: =IF(A12="","", IF(XLOOKUP(A12, INPUT_Rooms!$B:$B, INPUT_Rooms!$N:$N, "")="", $B$5, XLOOKUP(A12, INPUT_Rooms!$B:$B, INPUT_Rooms!$N:$N, ""))) | H12: =IF(A12="","", D12*XLOOKUP("PrepMinsPerSqft",Constants!$A$20:$A$40,Constants!$B$20:$B$40)*XLOOKUP(G12,Constants!$E$10:$E$30,Constants!$F$10:$F$30)) | I12: =IF(A12="","", D12*XLOOKUP("PaintMinsPerSqftPerCoat",Constants!$A$20:$A$40,Constants!$B$20:$B$40)*F12) | J12: =IF(A12="","", IF(E12="Full", D12*XLOOKUP("PrimerFullMinsPerSqft",Constants!$A$20:$A$40,Constants!$B$20:$B$40), IF(E12="Spot", D12*XLOOKUP("PrimerFullMinsPerSqft",Constants!$A$20:$A$40,Constants!$B$20:$B$40)*XLOOKUP("PrimerSpotFactor",Constants!$A$20:$A$40,Constants!$B$20:$B$40), 0))) | K12: =IF(A12="","", SUMPRODUCT((INPUT_Openings!$A:$A=$B$4)*(INPUT_Openings!$B:$B=A12)*(INPUT_Openings!$D:$D)*INPUT_Openings!$F:$F)) | L12: =IF($A12="","",IF($D12="", "",IFERROR(CEILING( ($D12*$F12) / IFERROR(XLOOKUP(XLOOKUP('Job Control'!$B$3, INPUT_JobSettings!$A:$A, INPUT_JobSettings!$B:$B, ""), Constants!$A:$A, Constants!$D:$D, ""), ""), 0.25), ""))) | M12: =IF($A12="","",IF($E12="None",0,IF($D12="", "",IFERROR(CEILING( ($D12*IF($E12="Full",1, XLOOKUP("PrimerSpotFactor",Constants!$A$10:$A$60,Constants!$B$10:$B$60))) / IFERROR(XLOOKUP(XLOOKUP('Job Control'!$B$3, INPUT_JobSettings!$A:$A, INPUT_JobSettings!$E:$E, ""), Constants!$A:$A, Constants!$D:$D, ""), ""), 0.25), "")))) | N12: =IF($A12="","",IFERROR($L12*IFERROR(XLOOKUP(XLOOKUP('Job Control'!$B$3, INPUT_JobSettings!$A:$A, INPUT_JobSettings!$B:$B, ""), Constants!$A:$A, Constants!$C:$C, 0), 0) + $M12*IFERROR(XLOOKUP(XLOOKUP('Job Control'!$B$3, INPUT_JobSettings!$A:$A, INPUT_JobSettings!$E:$E, ""), Constants!$A:$A, Constants!$C:$C, 0), 0),0)) | O12: =IF($A12="","", SUM($H12:$K12)) | P12: =IF($A12="","", $O12/60) | Q12: =IF($A12="","", $P12*IFERROR(IF(XLOOKUP('Job Control'!$B$3, INPUT_JobSettings!$A:$A, INPUT_JobSettings!$F:$F, "")<>"", XLOOKUP('Job Control'!$B$3, INPUT_JobSettings!$A:$A, INPUT_JobSettings!$F:$F, ""), $B$6), $B$6)) | R12: =IF($A12="","", ($Q12+$N12)*IFERROR(IF(XLOOKUP('Job Control'!$B$3, INPUT_JobSettings!$A:$A, INPUT_JobSettings!$G:$G, "")<>"", XLOOKUP('Job Control'!$B$3, INPUT_JobSettings!$A:$A, INPUT_JobSettings!$G:$G, ""), $B$7), $B$7)) | S12: =IF($A12="","", XLOOKUP($A12, INPUT_Rooms!$B:$B, INPUT_Rooms!$AH:$AH, ""))
A13: =IFERROR(INDEX(FILTER(INPUT_Rooms!$B$4:$B$83, INPUT_Rooms!$A$4:$A$83=$B$4, INPUT_Rooms!$K$4:$K$83="Y"), 3), "") | B13: =IF(A13="","", XLOOKUP(A13, FILTER(INPUT_Rooms!$B$4:$B$83, INPUT_Rooms!$A$4:$A$83=$B$4), FILTER(INPUT_Rooms!$C$4:$C$83, INPUT_Rooms!$A$4:$A$83=$B$4), "")) | C13: =IF(A13="","", "Y") | D13: =IF(A13="","", XLOOKUP(A13, INPUT_Rooms!$B:$B, INPUT_Rooms!$AD:$AD, "")) | E13: =IF(A13="","", XLOOKUP(A13, INPUT_Rooms!$B:$B, INPUT_Rooms!$L:$L, "")) | F13: =IF(A13="","", XLOOKUP(A13, INPUT_Rooms!$B:$B, INPUT_Rooms!$M:$M, "")) | G13: =IF(A13="","", IF(XLOOKUP(A13, INPUT_Rooms!$B:$B, INPUT_Rooms!$N:$N, "")="", $B$5, XLOOKUP(A13, INPUT_Rooms!$B:$B, INPUT_Rooms!$N:$N, ""))) | H13: =IF(A13="","", D13*XLOOKUP("PrepMinsPerSqft",Constants!$A$20:$A$40,Constants!$B$20:$B$40)*XLOOKUP(G13,Constants!$E$10:$E$30,Constants!$F$10:$F$30)) | I13: =IF(A13="","", D13*XLOOKUP("PaintMinsPerSqftPerCoat",Constants!$A$20:$A$40,Constants!$B$20:$B$40)*F13) | J13: =IF(A13="","", IF(E13="Full", D13*XLOOKUP("PrimerFullMinsPerSqft",Constants!$A$20:$A$40,Constants!$B$20:$B$40), IF(E13="Spot", D13*XLOOKUP("PrimerFullMinsPerSqft",Constants!$A$20:$A$40,Constants!$B$20:$B$40)*XLOOKUP("PrimerSpotFactor",Constants!$A$20:$A$40,Constants!$B$20:$B$40), 0))) | K13: =IF(A13="","", SUMPRODUCT((INPUT_Openings!$A:$A=$B$4)*(INPUT_Openings!$B:$B=A13)*(INPUT_Openings!$D:$D)*INPUT_Openings!$F:$F)) | L13: =IF($A13="","",IF($D13="", "",IFERROR(CEILING( ($D13*$F13) / IFERROR(XLOOKUP(XLOOKUP('Job Control'!$B$3, INPUT_JobSettings!$A:$A, INPUT_JobSettings!$B:$B, ""), Constants!$A:$A, Constants!$D:$D, ""), ""), 0.25), ""))) | M13: =IF($A13="","",IF($E13="None",0,IF($D13="", "",IFERROR(CEILING( ($D13*IF($E13="Full",1, XLOOKUP("PrimerSpotFactor",Constants!$A$10:$A$60,Constants!$B$10:$B$60))) / IFERROR(XLOOKUP(XLOOKUP('Job Control'!$B$3, INPUT_JobSettings!$A:$A, INPUT_JobSettings!$E:$E, ""), Constants!$A:$A, Constants!$D:$D, ""), ""), 0.25), "")))) | N13: =IF($A13="","",IFERROR($L13*IFERROR(XLOOKUP(XLOOKUP('Job Control'!$B$3, INPUT_JobSettings!$A:$A, INPUT_JobSettings!$B:$B, ""), Constants!$A:$A, Constants!$C:$C, 0), 0) + $M13*IFERROR(XLOOKUP(XLOOKUP('Job Control'!$B$3, INPUT_JobSettings!$A:$A, INPUT_JobSettings!$E:$E, ""), Constants!$A:$A, Constants!$C:$C, 0), 0),0)) | O13: =IF($A13="","", SUM($H13:$K13)) | P13: =IF($A13="","", $O13/60) | Q13: =IF($A13="","", $P13*IFERROR(IF(XLOOKUP('Job Control'!$B$3, INPUT_JobSettings!$A:$A, INPUT_JobSettings!$F:$F, "")<>"", XLOOKUP('Job Control'!$B$3, INPUT_JobSettings!$A:$A, INPUT_JobSettings!$F:$F, ""), $B$6), $B$6)) | R13: =IF($A13="","", ($Q13+$N13)*IFERROR(IF(XLOOKUP('Job Control'!$B$3, INPUT_JobSettings!$A:$A, INPUT_JobSettings!$G:$G, "")<>"", XLOOKUP('Job Control'!$B$3, INPUT_JobSettings!$A:$A, INPUT_JobSettings!$G:$G, ""), $B$7), $B$7)) | S13: =IF($A13="","", XLOOKUP($A13, INPUT_Rooms!$B:$B, INPUT_Rooms!$AH:$AH, ""))
A14: =IFERROR(INDEX(FILTER(INPUT_Rooms!$B$4:$B$83, INPUT_Rooms!$A$4:$A$83=$B$4, INPUT_Rooms!$K$4:$K$83="Y"), 4), "") | B14: =IF(A14="","", XLOOKUP(A14, FILTER(INPUT_Rooms!$B$4:$B$83, INPUT_Rooms!$A$4:$A$83=$B$4), FILTER(INPUT_Rooms!$C$4:$C$83, INPUT_Rooms!$A$4:$A$83=$B$4), "")) | C14: =IF(A14="","", "Y") | D14: =IF(A14="","", XLOOKUP(A14, INPUT_Rooms!$B:$B, INPUT_Rooms!$AD:$AD, "")) | E14: =IF(A14="","", XLOOKUP(A14, INPUT_Rooms!$B:$B, INPUT_Rooms!$L:$L, "")) | F14: =IF(A14="","", XLOOKUP(A14, INPUT_Rooms!$B:$B, INPUT_Rooms!$M:$M, "")) | G14: =IF(A14="","", IF(XLOOKUP(A14, INPUT_Rooms!$B:$B, INPUT_Rooms!$N:$N, "")="", $B$5, XLOOKUP(A14, INPUT_Rooms!$B:$B, INPUT_Rooms!$N:$N, ""))) | H14: =IF(A14="","", D14*XLOOKUP("PrepMinsPerSqft",Constants!$A$20:$A$40,Constants!$B$20:$B$40)*XLOOKUP(G14,Constants!$E$10:$E$30,Constants!$F$10:$F$30)) | I14: =IF(A14="","", D14*XLOOKUP("PaintMinsPerSqftPerCoat",Constants!$A$20:$A$40,Constants!$B$20:$B$40)*F14) | J14: =IF(A14="","", IF(E14="Full", D14*XLOOKUP("PrimerFullMinsPerSqft",Constants!$A$20:$A$40,Constants!$B$20:$B$40), IF(E14="Spot", D14*XLOOKUP("PrimerFullMinsPerSqft",Constants!$A$20:$A$40,Constants!$B$20:$B$40)*XLOOKUP("PrimerSpotFactor",Constants!$A$20:$A$40,Constants!$B$20:$B$40), 0))) | K14: =IF(A14="","", SUMPRODUCT((INPUT_Openings!$A:$A=$B$4)*(INPUT_Openings!$B:$B=A14)*(INPUT_Openings!$D:$D)*INPUT_Openings!$F:$F)) | L14: =IF($A14="","",IF($D14="", "",IFERROR(CEILING( ($D14*$F14) / IFERROR(XLOOKUP(XLOOKUP('Job Control'!$B$3, INPUT_JobSettings!$A:$A, INPUT_JobSettings!$B:$B, ""), Constants!$A:$A, Constants!$D:$D, ""), ""), 0.25), ""))) | M14: =IF($A14="","",IF($E14="None",0,IF($D14="", "",IFERROR(CEILING( ($D14*IF($E14="Full",1, XLOOKUP("PrimerSpotFactor",Constants!$A$10:$A$60,Constants!$B$10:$B$60))) / IFERROR(XLOOKUP(XLOOKUP('Job Control'!$B$3, INPUT_JobSettings!$A:$A, INPUT_JobSettings!$E:$E, ""), Constants!$A:$A, Constants!$D:$D, ""), ""), 0.25), "")))) | N14: =IF($A14="","",IFERROR($L14*IFERROR(XLOOKUP(XLOOKUP('Job Control'!$B$3, INPUT_JobSettings!$A:$A, INPUT_JobSettings!$B:$B, ""), Constants!$A:$A, Constants!$C:$C, 0), 0) + $M14*IFERROR(XLOOKUP(XLOOKUP('Job Control'!$B$3, INPUT_JobSettings!$A:$A, INPUT_JobSettings!$E:$E, ""), Constants!$A:$A, Constants!$C:$C, 0), 0),0)) | O14: =IF($A14="","", SUM($H14:$K14)) | P14: =IF($A14="","", $O14/60) | Q14: =IF($A14="","", $P14*IFERROR(IF(XLOOKUP('Job Control'!$B$3, INPUT_JobSettings!$A:$A, INPUT_JobSettings!$F:$F, "")<>"", XLOOKUP('Job Control'!$B$3, INPUT_JobSettings!$A:$A, INPUT_JobSettings!$F:$F, ""), $B$6), $B$6)) | R14: =IF($A14="","", ($Q14+$N14)*IFERROR(IF(XLOOKUP('Job Control'!$B$3, INPUT_JobSettings!$A:$A, INPUT_JobSettings!$G:$G, "")<>"", XLOOKUP('Job Control'!$B$3, INPUT_JobSettings!$A:$A, INPUT_JobSettings!$G:$G, ""), $B$7), $B$7)) | S14: =IF($A14="","", XLOOKUP($A14, INPUT_Rooms!$B:$B, INPUT_Rooms!$AH:$AH, ""))
A15: =IFERROR(INDEX(FILTER(INPUT_Rooms!$B$4:$B$83, INPUT_Rooms!$A$4:$A$83=$B$4, INPUT_Rooms!$K$4:$K$83="Y"), 5), "") | B15: =IF(A15="","", XLOOKUP(A15, FILTER(INPUT_Rooms!$B$4:$B$83, INPUT_Rooms!$A$4:$A$83=$B$4), FILTER(INPUT_Rooms!$C$4:$C$83, INPUT_Rooms!$A$4:$A$83=$B$4), "")) | C15: =IF(A15="","", "Y") | D15: =IF(A15="","", XLOOKUP(A15, INPUT_Rooms!$B:$B, INPUT_Rooms!$AD:$AD, "")) | E15: =IF(A15="","", XLOOKUP(A15, INPUT_Rooms!$B:$B, INPUT_Rooms!$L:$L, "")) | F15: =IF(A15="","", XLOOKUP(A15, INPUT_Rooms!$B:$B, INPUT_Rooms!$M:$M, "")) | G15: =IF(A15="","", IF(XLOOKUP(A15, INPUT_Rooms!$B:$B, INPUT_Rooms!$N:$N, "")="", $B$5, XLOOKUP(A15, INPUT_Rooms!$B:$B, INPUT_Rooms!$N:$N, ""))) | H15: =IF(A15="","", D15*XLOOKUP("PrepMinsPerSqft",Constants!$A$20:$A$40,Constants!$B$20:$B$40)*XLOOKUP(G15,Constants!$E$10:$E$30,Constants!$F$10:$F$30)) | I15: =IF(A15="","", D15*XLOOKUP("PaintMinsPerSqftPerCoat",Constants!$A$20:$A$40,Constants!$B$20:$B$40)*F15) | J15: =IF(A15="","", IF(E15="Full", D15*XLOOKUP("PrimerFullMinsPerSqft",Constants!$A$20:$A$40,Constants!$B$20:$B$40), IF(E15="Spot", D15*XLOOKUP("PrimerFullMinsPerSqft",Constants!$A$20:$A$40,Constants!$B$20:$B$40)*XLOOKUP("PrimerSpotFactor",Constants!$A$20:$A$40,Constants!$B$20:$B$40), 0))) | K15: =IF(A15="","", SUMPRODUCT((INPUT_Openings!$A:$A=$B$4)*(INPUT_Openings!$B:$B=A15)*(INPUT_Openings!$D:$D)*INPUT_Openings!$F:$F)) | L15: =IF($A15="","",IF($D15="", "",IFERROR(CEILING( ($D15*$F15) / IFERROR(XLOOKUP(XLOOKUP('Job Control'!$B$3, INPUT_JobSettings!$A:$A, INPUT_JobSettings!$B:$B, ""), Constants!$A:$A, Constants!$D:$D, ""), ""), 0.25), ""))) | M15: =IF($A15="","",IF($E15="None",0,IF($D15="", "",IFERROR(CEILING( ($D15*IF($E15="Full",1, XLOOKUP("PrimerSpotFactor",Constants!$A$10:$A$60,Constants!$B$10:$B$60))) / IFERROR(XLOOKUP(XLOOKUP('Job Control'!$B$3, INPUT_JobSettings!$A:$A, INPUT_JobSettings!$E:$E, ""), Constants!$A:$A, Constants!$D:$D, ""), ""), 0.25), "")))) | N15: =IF($A15="","",IFERROR($L15*IFERROR(XLOOKUP(XLOOKUP('Job Control'!$B$3, INPUT_JobSettings!$A:$A, INPUT_JobSettings!$B:$B, ""), Constants!$A:$A, Constants!$C:$C, 0), 0) + $M15*IFERROR(XLOOKUP(XLOOKUP('Job Control'!$B$3, INPUT_JobSettings!$A:$A, INPUT_JobSettings!$E:$E, ""), Constants!$A:$A, Constants!$C:$C, 0), 0),0)) | O15: =IF($A15="","", SUM($H15:$K15)) | P15: =IF($A15="","", $O15/60) | Q15: =IF($A15="","", $P15*IFERROR(IF(XLOOKUP('Job Control'!$B$3, INPUT_JobSettings!$A:$A, INPUT_JobSettings!$F:$F, "")<>"", XLOOKUP('Job Control'!$B$3, INPUT_JobSettings!$A:$A, INPUT_JobSettings!$F:$F, ""), $B$6), $B$6)) | R15: =IF($A15="","", ($Q15+$N15)*IFERROR(IF(XLOOKUP('Job Control'!$B$3, INPUT_JobSettings!$A:$A, INPUT_JobSettings!$G:$G, "")<>"", XLOOKUP('Job Control'!$B$3, INPUT_JobSettings!$A:$A, INPUT_JobSettings!$G:$G, ""), $B$7), $B$7)) | S15: =IF($A15="","", XLOOKUP($A15, INPUT_Rooms!$B:$B, INPUT_Rooms!$AH:$AH, ""))
